2023-08-17 11:00:07,398 - INFO - Order Status App started.
2023-08-17 11:00:15,223 - INFO - Execution time: 7.826099872589111
2023-08-17 12:20:46,856 - INFO - Order Status App started.
2023-08-17 12:20:48,246 - ERROR - An unexpected error occurred
Traceback (most recent call last):
  File "C:\Users\Mitchell\AppData\Local\Programs\Python\Python39\lib\site-packages\pandas\core\indexes\base.py", line 3621, in get_loc
    return self._engine.get_loc(casted_key)
  File "pandas\_libs\index.pyx", line 136, in pandas._libs.index.IndexEngine.get_loc
  File "pandas\_libs\index.pyx", line 163, in pandas._libs.index.IndexEngine.get_loc
  File "pandas\_libs\hashtable_class_helper.pxi", line 5198, in pandas._libs.hashtable.PyObjectHashTable.get_item
  File "pandas\_libs\hashtable_class_helper.pxi", line 5206, in pandas._libs.hashtable.PyObjectHashTable.get_item
KeyError: 'SHIPDT'

The above exception was the direct cause of the following exception:

Traceback (most recent call last):
  File "C:\Users\Mitchell\PycharmProjects\dempseysystems.github.io\main.py", line 155, in <module>
    ordhfile = export_ordhfile(connection, database_name)
  File "C:\Users\Mitchell\PycharmProjects\dempseysystems.github.io\main.py", line 45, in export_ordhfile
    ship_date = ordhfile["SHIPDT"].to_list()
  File "C:\Users\Mitchell\AppData\Local\Programs\Python\Python39\lib\site-packages\pandas\core\frame.py", line 3505, in __getitem__
    indexer = self.columns.get_loc(key)
  File "C:\Users\Mitchell\AppData\Local\Programs\Python\Python39\lib\site-packages\pandas\core\indexes\base.py", line 3623, in get_loc
    raise KeyError(key) from err
KeyError: 'SHIPDT'
2023-08-17 12:20:48,257 - INFO - Execution time: 1.4014551639556885
2023-08-17 12:22:04,093 - INFO - Order Status App started.
2023-08-17 12:22:17,918 - INFO - Execution time: 13.824562311172485
2023-08-17 13:07:46,043 - INFO - Order Status App started.
2023-08-17 13:08:00,745 - INFO - Execution time: 14.70325493812561
2023-08-17 13:17:17,323 - INFO - Order Status App started.
2023-08-17 13:17:18,681 - ERROR - An unexpected error occurred
Traceback (most recent call last):
  File "C:\Users\Mitchell\PycharmProjects\dempseysystems.github.io\main.py", line 171, in <module>
    ordhfile = export_ordhfile(connection, database_name)
  File "C:\Users\Mitchell\PycharmProjects\dempseysystems.github.io\main.py", line 61, in export_ordhfile
    ordhfile["SHIP_DATE"] = np.where(ordhfile["STATUS"].isin(confirmed_statuses), ordhfile["SHIP_DATE"], "To be "
  File "<__array_function__ internals>", line 180, in where
TypeError: The DType <class 'numpy.dtype[datetime64]'> could not be promoted by <class 'numpy.dtype[str_]'>. This means that no common DType exists for the given inputs. For example they cannot be stored in a single array unless the dtype is `object`. The full list of DTypes is: (<class 'numpy.dtype[datetime64]'>, <class 'numpy.dtype[str_]'>)
2023-08-17 13:17:18,681 - INFO - Execution time: 1.3581268787384033
2023-08-17 13:19:43,636 - INFO - Order Status App started.
2023-08-17 13:19:57,027 - INFO - Execution time: 13.390718221664429
2023-08-17 13:24:09,664 - INFO - Order Status App started.
2023-08-17 13:25:57,603 - INFO - Execution time: 107.93875241279602
2023-08-17 13:26:08,545 - INFO - Order Status App started.
2023-08-17 13:26:15,096 - INFO - Execution time: 6.5507447719573975
2023-08-17 16:11:39,585 - INFO - Order Status App started.
2023-08-17 16:11:47,615 - INFO - Execution time: 8.030316352844238
2023-08-17 16:30:38,984 - INFO - Order Status App started.
2023-08-17 16:30:46,851 - INFO - Execution time: 7.867921829223633
2023-08-17 16:49:36,782 - INFO - Order Status App started.
2023-08-17 16:49:43,548 - INFO - Execution time: 6.765322208404541
2023-08-17 16:50:28,823 - INFO - Order Status App started.
2023-08-17 16:50:42,098 - INFO - Execution time: 13.274996995925903
2023-08-17 16:57:43,464 - INFO - Order Status App started.
2023-08-17 16:57:56,637 - INFO - Execution time: 13.17403793334961
2023-08-17 17:10:49,746 - INFO - Order Status App started.
2023-08-17 17:11:05,356 - INFO - Execution time: 15.609506845474243
2023-08-17 17:11:14,163 - INFO - Order Status App started.
2023-08-17 17:11:29,352 - INFO - Execution time: 15.189566850662231
2023-08-17 17:39:15,362 - INFO - Order Status App started.
2023-08-17 17:41:05,031 - INFO - Execution time: 109.66791605949402
2023-08-17 19:29:00,172 - INFO - Order Status App started.
2023-08-17 19:29:14,337 - INFO - Execution time: 14.164432287216187
2023-08-17 19:31:57,200 - INFO - Order Status App started.
2023-08-17 19:32:14,566 - INFO - Execution time: 17.367127418518066
2023-08-17 19:42:18,500 - INFO - Order Status App started.
2023-08-17 19:42:34,853 - INFO - Execution time: 16.35489511489868
2023-08-17 19:44:27,909 - INFO - Order Status App started.
2023-08-17 19:44:37,094 - INFO - Execution time: 9.185646533966064
2023-08-17 19:56:26,473 - INFO - Order Status App started.
2023-08-17 19:56:34,678 - INFO - Execution time: 8.205044507980347
2023-08-18 09:42:27,856 - INFO - Order Status App started.
2023-08-18 09:42:29,101 - ERROR - An unexpected error occurred
Traceback (most recent call last):
  File "C:\Users\Mitchell\PycharmProjects\dempseysystems.github.io\main.py", line 304, in <module>
    ordhfile = export_ordhfile(connection, database_name)
  File "C:\Users\Mitchell\PycharmProjects\dempseysystems.github.io\main.py", line 192, in export_ordhfile
    ordhfile_french['SHIP_DATE'] = ordhfile_french['SHIP_DATE'].apply(format_date_to_french)
  File "C:\Users\Mitchell\AppData\Local\Programs\Python\Python39\lib\site-packages\pandas\core\series.py", line 4433, in apply
    return SeriesApply(self, func, convert_dtype, args, kwargs).apply()
  File "C:\Users\Mitchell\AppData\Local\Programs\Python\Python39\lib\site-packages\pandas\core\apply.py", line 1082, in apply
    return self.apply_standard()
  File "C:\Users\Mitchell\AppData\Local\Programs\Python\Python39\lib\site-packages\pandas\core\apply.py", line 1137, in apply_standard
    mapped = lib.map_infer(
  File "pandas\_libs\lib.pyx", line 2870, in pandas._libs.lib.map_infer
  File "C:\Users\Mitchell\PycharmProjects\dempseysystems.github.io\main.py", line 186, in format_date_to_french
    formatted_date = date.strftime('%Y-%b-%d')
  File "pandas\_libs\tslibs\nattype.pyx", line 75, in pandas._libs.tslibs.nattype._make_error_func.f
ValueError: NaTType does not support strftime
2023-08-18 09:42:29,103 - INFO - Execution time: 1.246567726135254
2023-08-18 09:46:18,086 - INFO - Order Status App started.
2023-08-18 09:46:25,952 - INFO - Execution time: 7.865778923034668
2023-08-18 09:48:50,599 - INFO - Order Status App started.
2023-08-18 09:48:57,933 - INFO - Execution time: 7.334304571151733
2023-08-18 11:07:07,471 - INFO - Order Status App started.
2023-08-18 11:07:16,312 - INFO - Execution time: 8.842411994934082
